Traceback (most recent call last):
  File "/Users/drm/miniforge3/envs/Jupyter_Book_Turing_Way_Demo/lib/python3.11/site-packages/jupyter_cache/executors/utils.py", line 58, in single_nb_execution
    executenb(
  File "/Users/drm/miniforge3/envs/Jupyter_Book_Turing_Way_Demo/lib/python3.11/site-packages/nbclient/client.py", line 1305, in execute
    return NotebookClient(nb=nb, resources=resources, km=km, **kwargs).execute()
           ^^^^^^^^^^^^^^^^^^^^^^^^^^^^^^^^^^^^^^^^^^^^^^^^^^^^^^^^^^^^^^^^^^^^^
  File "/Users/drm/miniforge3/envs/Jupyter_Book_Turing_Way_Demo/lib/python3.11/site-packages/jupyter_core/utils/__init__.py", line 165, in wrapped
    return loop.run_until_complete(inner)
           ^^^^^^^^^^^^^^^^^^^^^^^^^^^^^^
  File "/Users/drm/miniforge3/envs/Jupyter_Book_Turing_Way_Demo/lib/python3.11/asyncio/base_events.py", line 653, in run_until_complete
    return future.result()
           ^^^^^^^^^^^^^^^
  File "/Users/drm/miniforge3/envs/Jupyter_Book_Turing_Way_Demo/lib/python3.11/site-packages/nbclient/client.py", line 705, in async_execute
    await self.async_execute_cell(
  File "/Users/drm/miniforge3/envs/Jupyter_Book_Turing_Way_Demo/lib/python3.11/site-packages/nbclient/client.py", line 1058, in async_execute_cell
    await self._check_raise_for_error(cell, cell_index, exec_reply)
  File "/Users/drm/miniforge3/envs/Jupyter_Book_Turing_Way_Demo/lib/python3.11/site-packages/nbclient/client.py", line 914, in _check_raise_for_error
    raise CellExecutionError.from_cell_and_msg(cell, exec_reply_content)
nbclient.exceptions.CellExecutionError: An error occurred while executing the following cell:
------------------
import numpy as np
import matplotlib.pyplot as plt
from mpl_toolkits.mplot3d import Axes3D

# Generate values for x
x = np.linspace(-2*np.pi, 2*np.pi, 800)

# Calculate the real and imaginary parts of e^(ix)
re = np.cos(x)  # Real part
im = np.sin(x)  # Imaginary part

# Plotting
fig = plt.figure(figsize=(20, 16))
ax = fig.add_subplot(111, projection='3d')

# Plotting real and imaginary parts
ax.plot(x, re, zs=0, zdir='y', label='Real Part (cos(x))', color='blue')
ax.plot(x, im, zs=0, zdir='x', label='Imaginary Part (sin(x))', color='red')

# Plotting the complex function e^(ix)
ax.plot(x, re, im, label='e^(ix)', color='green')

# Labels and title
ax.set_xlabel('X axis')
ax.set_ylabel('Real Part')
ax.set_zlabel('Imaginary Part')
ax.set_title('3D Plot of Euler\'s Formula e^(ix)')

# Legend
ax.legend()

plt.show()
------------------


[0;31m---------------------------------------------------------------------------[0m
[0;31mModuleNotFoundError[0m                       Traceback (most recent call last)
Cell [0;32mIn[1], line 1[0m
[0;32m----> 1[0m [38;5;28;01mimport[39;00m [38;5;21;01mnumpy[39;00m [38;5;28;01mas[39;00m [38;5;21;01mnp[39;00m
[1;32m      2[0m [38;5;28;01mimport[39;00m [38;5;21;01mmatplotlib[39;00m[38;5;21;01m.[39;00m[38;5;21;01mpyplot[39;00m [38;5;28;01mas[39;00m [38;5;21;01mplt[39;00m
[1;32m      3[0m [38;5;28;01mfrom[39;00m [38;5;21;01mmpl_toolkits[39;00m[38;5;21;01m.[39;00m[38;5;21;01mmplot3d[39;00m [38;5;28;01mimport[39;00m Axes3D

[0;31mModuleNotFoundError[0m: No module named 'numpy'

